Workbook

Sheet Assumptions
A1: DietBuddy — free-tier AI cost vs ad revenue
A2: Edit the yellow cells (blue text). Every other sheet recalculates from them. Values are estimates, not measured data; replace them with real AdMob and ai_usage figures after launch.
A4: Model prices (USD per million tokens)
A5: Haiku 4.5 — input | B5: 1 | C5: Anthropic list price (claude-api skill, cached 2026-09-25)
A6: Haiku 4.5 — output | B6: 5 | C6: Anthropic list price
A7: Haiku 4.5 — cache read | B7: 0.1 | C7: 0.1x input
A8: Sonnet 5 — input | B8: 2 | C8: Anthropic list price; Premium model
A9: Sonnet 5 — output | B9: 10 | C9: Anthropic list price
A10: Sonnet 5 — cache read | B10: 0.2 | C10: 0.1x input
A11: Tokens per AI call (estimates; measure with ai_usage)
A12: Coach message — input tokens | B12: 4000 | C12: System prompt + user context + up to 12 history messages
A13: Coach message — output tokens | B13: 300 | C13: Reply JSON
A14: Coach — share of input read from cache (free, Haiku) | B14: 0 | C14: Haiku 4.5 caches only prompts >= 4,096 tokens: ~0 for short chats
A15: Coach — share of input read from cache (Premium, Sonnet) | B15: 0.6 | C15: Sonnet 5 caches prompts >= 1,024 tokens; later messages in a chat read the prefix
A16: Meal plan — input tokens | B16: 2000 | C16: Rules + targets + preferences
A17: Meal plan — output tokens | B17: 1200 | C17: Four dishes with ingredients and steps
A18: Meal plan — attempts per plan (diet-rule retries) | B18: 1.3 | C18: Up to 3 attempts when a dish breaks a rule
A19: Translation (non-English) — input tokens | B19: 800 | C19: Dish texts sent back for translation
A20: Translation (non-English) — output tokens | B20: 900
A21: Share of users not using English | B21: 0.5 | C21: German, French, Spanish, Italian, Greek
A22: Another idea — input tokens | B22: 1800
A23: Another idea — output tokens | B23: 400
A24: Another idea — attempts | B24: 1.2
A25: Food photo scan — input tokens | B25: 2300 | C25: Image ~1,500 + prompt
A26: Food photo scan — output tokens | B26: 300
A27: Food photo scan — attempts | B27: 1.1
A28: Ads (AdMob, EU; estimates)
A29: Banner eCPM (USD per 1,000 impressions) | B29: 0.5 | C29: Assumption: EU banners typically $0.3–1.0
A30: Banner impressions per active day | B30: 15 | C30: Home + Progress banners with refresh
A31: Rewarded video eCPM (USD per 1,000 views) | B31: 8 | C31: Assumption: EU rewarded typically $6–15
A32: Share of impressions non-personalised | B32: 0.6 | C32: All iOS (no ATT) + EU users who decline consent
A33: Non-personalised earnings vs personalised | B33: 0.6 | C33: NPA ads typically earn 30–50% less
A34: Free-tier limits and budget (app_config)
A35: Base AI budget per day (USD) | B35: 0.04 | C35: ai_free_daily_budget_usd: a backstop sized to the free allowance
A36: Extra AI budget per rewarded video (USD) | B36: 0.01 | C36: ai_budget_per_boost_usd: the cost of what a video adds
A37: Rewarded videos per day that count (max) | B37: 3 | C37: ai_boosts_daily_max
A38: Usage per active day — typical free user
A39: Meal plans | B39: 1 | C39: Today's plan is always made
A40: Coach messages | B40: 1
A41: Another idea | B41: 0.3
...

Sheet Feature cost
A1: AI cost per call (USD)
A3: Feature | B3: Free (Haiku) | C3: Premium (Sonnet) | D3: How it is calculated
A4: Coach message | B4: =1*(Assumptions!$B$12*(1-Assumptions!$B$14)*Assumptions!$B$5+Assumptions!$B$12*Assumptions!$B$14*Assumptions!$B$7+Assumptions!$B$13*Assumptions!$B$6)/1000000 | C4: =1*(Assumptions!$B$12*(1-Assumptions!$B$15)*Assumptions!$B$8+Assumptions!$B$12*Assumptions!$B$15*Assumptions!$B$10+Assumptions!$B$13*Assumptions!$B$9)/1000000 | D4: input (part from cache) + output
A5: Meal plan | B5: =Assumptions!$B$18*(Assumptions!$B$16*(1-0)*Assumptions!$B$5+Assumptions!$B$16*0*Assumptions!$B$7+Assumptions!$B$17*Assumptions!$B$6)/1000000 | C5: =Assumptions!$B$18*(Assumptions!$B$16*(1-0)*Assumptions!$B$8+Assumptions!$B$16*0*Assumptions!$B$10+Assumptions!$B$17*Assumptions!$B$9)/1000000 | D5: x attempts
A6: Translation per plan (weighted by non-English share) | B6: =Assumptions!$B$21*(Assumptions!$B$19*Assumptions!$B$5+Assumptions!$B$20*Assumptions!$B$6)/1000000 | C6: =Assumptions!$B$21*(Assumptions!$B$19*Assumptions!$B$8+Assumptions!$B$20*Assumptions!$B$9)/1000000 | D6: only for non-English users
A7: Another idea | B7: =Assumptions!$B$24*(Assumptions!$B$22*(1-0)*Assumptions!$B$5+Assumptions!$B$22*0*Assumptions!$B$7+Assumptions!$B$23*Assumptions!$B$6)/1000000 | C7: =Assumptions!$B$24*(Assumptions!$B$22*(1-0)*Assumptions!$B$8+Assumptions!$B$22*0*Assumptions!$B$10+Assumptions!$B$23*Assumptions!$B$9)/1000000 | D7: x attempts
A8: Food photo scan | B8: =Assumptions!$B$27*(Assumptions!$B$25*(1-0)*Assumptions!$B$5+Assumptions!$B$25*0*Assumptions!$B$7+Assumptions!$B$26*Assumptions!$B$6)/1000000 | C8: =Assumptions!$B$27*(Assumptions!$B$25*(1-0)*Assumptions!$B$8+Assumptions!$B$25*0*Assumptions!$B$10+Assumptions!$B$26*Assumptions!$B$9)/1000000 | D8: x attempts

Sheet Free user P&L
A1: Free user: per active day and per month (USD)
B3: Typical | C3: Heavy (3 videos)
A4: Banner revenue per active day | B4: =Assumptions!$B$30*Assumptions!$B$29/1000*(1-Assumptions!$B$32*(1-Assumptions!$B$33)) | C4: =Assumptions!$B$30*Assumptions!$B$29/1000*(1-Assumptions!$B$32*(1-Assumptions!$B$33))
A5: Rewarded revenue per active day | B5: =Assumptions!$B$43*Assumptions!$B$31/1000*(1-Assumptions!$B$32*(1-Assumptions!$B$33)) | C5: =Assumptions!$B$49*Assumptions!$B$31/1000*(1-Assumptions!$B$32*(1-Assumptions!$B$33))
A6: Ad revenue per active day | B6: =B4+B5 | C6: =C4+C5
A7: AI cost without the budget cap | B7: =Assumptions!$B$39*('Feature cost'!$B$5+'Feature cost'!$B$6)+Assumptions!$B$40*'Feature cost'!$B$4+Assumptions!$B$41*'Feature cost'!$B$7+Assumptions!$B$42*'Feature cost'!$B$8 | C7: =Assumptions!$B$45*('Feature cost'!$B$5+'Feature cost'!$B$6)+Assumptions!$B$46*'Feature cost'!$B$4+Assumptions!$B$47*'Feature cost'!$B$7+Assumptions!$B$48*'Feature cost'!$B$8
A8: Daily AI budget (base + videos, capped) | B8: =Assumptions!$B$35+MIN(Assumptions!$B$43,Assumptions!$B$37)*Assumptions!$B$36 | C8: =Assumptions!$B$35+MIN(Assumptions!$B$49,Assumptions!$B$37)*Assumptions!$B$36
A9: AI cost per active day (after the cap; the plan always runs) | B9: =MIN(B7,MAX(B8,Assumptions!$B$39*('Feature cost'!$B$5+'Feature cost'!$B$6))) | C9: =MIN(C7,MAX(C8,Assumptions!$B$45*('Feature cost'!$B$5+'Feature cost'!$B$6)))
A10: Contribution per active day | B10: =B6-B9 | C10: =C6-C9
A11: Margin per active day | B11: =IF(B6=0,0,B10/B6) | C11: =IF(C6=0,0,C10/C6)
A12: Per month
A13: Ad revenue per month | B13: =B6*Assumptions!$B$51 | C13: =C6*Assumptions!$B$51
A14: AI cost per month | B14: =B9*Assumptions!$B$51 | C14: =C9*Assumptions!$B$51
A15: Infrastructure per month | B15: =Assumptions!$B$52 | C15: =Assumptions!$B$52
A16: Contribution per month | B16: =B13-B14-B15 | C16: =C13-C14-C15
A17: Margin per month | B17: =IF(B13=0,0,B16/B13) | C17: =IF(C13=0,0,C16/C13)
A18: Months of contribution to pay one SMS sign-up code | B18: =IF(B16<=0,"never",Assumptions!$B$53/B16) | C18: =IF(C16<=0,"never",Assumptions!$B$53/C16)

Sheet Premium & blended
A1: Premium economics and blended result per monthly user (USD)
A3: Net revenue per Premium user per month | B3: =Assumptions!$B$55*(1-Assumptions!$B$56)
A4: Premium AI cost per month (coach) | B4: =Assumptions!$B$58*Assumptions!$B$59*'Feature cost'!$C$4
A5: Premium AI cost per month (other) | B5: =Assumptions!$B$58*Assumptions!$B$60
A6: Contribution per Premium user per month | B6: =B3-B4-B5
A7: Free user contribution per month (typical) | B7: ='Free user P&L'!$B$16
A8: Blended contribution per monthly user | B8: =Assumptions!$B$57*B6+(1-Assumptions!$B$57)*B7
A9: ...of which from Premium | B9: =Assumptions!$B$57*B6
A10: ...of which from ads (free users) | B10: =(1-Assumptions!$B$57)*B7

Sheet Break-even
A1: Break-even ad rates for a typical free user
A3: Typical AI cost per active day | B3: ='Free user P&L'!$B$9
A4: Banner revenue per active day | B4: ='Free user P&L'!$B$4
A5: Rewarded eCPM needed to cover AI (at this banner rate) | B5: =IF(Assumptions!$B$43=0,0,MAX(0,(B3-B4))/Assumptions!$B$43*1000/(1-Assumptions!$B$32*(1-Assumptions!$B$33)))
A6: Banner eCPM needed with no rewarded videos | B6: =IF(Assumptions!$B$30=0,0,B3/Assumptions!$B$30*1000/(1-Assumptions!$B$32*(1-Assumptions!$B$33)))
A8: Ad eCPMs are after the non-personalised adjustment set on Assumptions.
